outputs/states_InventorySkew_SellPressure.csv
timestamp,strategy,regime,fair_price,best_bid,best_ask,recent_volatility,inventory,cash,pnl,bid_depth,ask_depth
1,InventorySkew,SellPressure,99.984057,99.950000,100.050000,0.000957,0,0.000000,0.000000,995,1000
2,InventorySkew,SellPressure,99.998466,99.950000,100.050000,0.001764,0,0.000000,0.000000,995,998
3,InventorySkew,SellPressure,99.981736,99.950000,100.050000,0.002662,0,0.000000,0.000000,975,998
4,InventorySkew,SellPressure,99.982322,99.950000,100.050000,0.002537,0,0.000000,0.000000,975,1009
5,InventorySkew,SellPressure,99.980581,99.951333,100.050000,0.002489,0,0.000000,0.000000,984,1009
6,InventorySkew,SellPressure,99.976343,99.951333,100.040436,0.002594,0,0.000000,0.000000,984,1019
7,InventorySkew,SellPressure,99.967322,99.950000,100.040436,0.002980,0,0.000000,0.000000,973,1019
8,InventorySkew,SellPressure,99.964055,99.950000,100.040436,0.002997,0,0.000000,0.000000,973,1031
9,InventorySkew,SellPressure,99.959968,99.950000,100.009057,0.003063,0,0.000000,0.000000,973,1041
10,InventorySkew,SellPressure,99.949555,99.950000,99.999555,0.003504,0,0.000000,0.000000,979,1051
11,InventorySkew,SellPressure,99.936849,99.950000,99.999555,0.004056,0,0.000000,0.000000,969,1051
12,InventorySkew,SellPressure,99.937328,99.950000,99.999555,0.003841,0,0.000000,0.000000,969,1069
13,InventorySkew,SellPressure,99.935398,99.950000,99.999555,0.003726,0,0.000000,0.000000,981,1069
14,InventorySkew,SellPressure,99.938243,99.950000,99.999555,0.003673,0,0.000000,0.000000,981,1076
15,InventorySkew,SellPressure,99.946203,99.950000,99.999555,0.003931,-4,399.998220,0.213409,981,1072
16,InventorySkew,SellPressure,99.961319,99.950000,99.999555,0.004602,-8,799.996440,0.305884,981,1068
17,InventorySkew,SellPressure,99.977939,99.950000,100.040436,0.005323,-10,999.995551,0.216158,981,1049
18,InventorySkew,SellPressure,99.969777,99.950000,100.040436,0.005493,-10,999.995551,0.297780,978,1049
19,InventorySkew,SellPressure,99.964859,99.950000,100.040436,0.005459,-10,999.995551,0.346959,978,1052
20,InventorySkew,SellPressure,99.962215,99.950000,100.050000,0.005290,0,-0.475758,-0.475758,978,1062
21,InventorySkew,SellPressure,99.958997,99.950000,100.050000,0.005166,0,-0.475758,-0.475758,978,1078
22,InventorySkew,SellPressure,99.942454,99.900000,100.050000,0.005848,0,-0.475758,-0.475758,968,1078
23,InventorySkew,SellPressure,99.927529,99.900000,100.050000,0.006393,0,-0.475758,-0.475758,955,1078
24,InventorySkew,SellPressure,99.911328,99.900000,100.050000,0.006981,0,-0.475758,-0.475758,947,1078
25,InventorySkew,SellPressure,99.911659,99.900000,100.050000,0.006582,0,-0.475758,-0.475758,947,1094
26,InventorySkew,SellPressure,99.896428,99.900000,100.050000,0.007101,0,-0.475758,-0.475758,945,1094
27,InventorySkew,SellPressure,99.909416,99.900000,100.050000,0.007455,0,-0.475758,-0.475758,945,1077
28,InventorySkew,SellPressure,99.895197,99.900000,100.050000,0.007860,0,-0.475758,-0.475758,934,1077
29,InventorySkew,SellPressure,99.883720,99.899555,100.050000,0.008077,8,-799.672199,-0.602435,914,1077
30,InventorySkew,SellPressure,99.895612,99.850000,100.050000,0.008306,0,-0.872199,-0.872199,914,1062
31,InventorySkew,SellPressure,99.893938,99.850000,100.041836,0.007908,0,-0.872199,-0.872199,914,1082
32,InventorySkew,SellPressure,99.894375,99.850000,99.941530,0.007460,0,-0.872199,-0.872199,914,1100
33,InventorySkew,SellPressure,99.878395,99.850000,99.941530,0.007971,0,-0.872199,-0.872199,911,1100
34,InventorySkew,SellPressure,99.865965,99.850000,99.941530,0.008239,0,-0.872199,-0.872199,898,1100
35,InventorySkew,SellPressure,99.862900,99.850000,99.909342,0.007928,0,-0.872199,-0.872199,898,1103
36,InventorySkew,SellPressure,99.855402,99.850000,99.909342,0.007902,0,-0.872199,-0.872199,881,1103
37,InventorySkew,SellPressure,99.856055,99.850000,99.909342,0.007468,0,-0.872199,-0.872199,881,1119
38,InventorySkew,SellPressure,99.853800,99.850000,99.909342,0.007155,0,-0.872199,-0.872199,892,1119
39,InventorySkew,SellPressure,99.851070,99.850000,99.909342,0.006889,0,-0.872199,-0.872199,906,1119
40,InventorySkew,SellPressure,99.846876,99.850000,99.896876,0.006728,0,-0.872199,-0.872199,928,1129
41,InventorySkew,SellPressure,99.848463,99.850000,99.896876,0.006419,0,-0.872199,-0.872199,928,1141
42,InventorySkew,SellPressure,99.853390,99.850000,99.863749,0.006330,0,-0.872199,-0.872199,928,1155
43,InventorySkew,SellPressure,99.851065,99.850000,99.863749,0.006089,0,-0.872199,-0.872199,928,1172
44,InventorySkew,SellPressure,99.848638,99.850000,99.863749,0.005870,0,-0.872199,-0.872199,928,1188
45,InventorySkew,SellPressure,99.856654,99.850000,99.896876,0.005998,-6,598.509056,-0.630869,928,1168
46,InventorySkew,SellPressure,99.854977,99.850000,99.896876,0.005739,-6,598.509056,-0.620806,928,1170
47,InventorySkew,SellPressure,99.857436,99.850000,99.896876,0.005542,-6,598.509056,-0.635560,928,1179
48,InventorySkew,SellPressure,99.844893,99.839761,99.896876,0.005962,-6,598.509056,-0.560304,919,1179
49,InventorySkew,SellPressure,99.849262,99.839761,99.896876,0.005867,-6,598.509056,-0.586516,919,1184
50,InventorySkew,SellPressure,99.850072,99.890072,99.896876,0.005563,-6,598.509056,-0.591378,942,1194
51,InventorySkew,SellPressure,99.864258,99.890072,99.929460,0.006081,-10,998.096560,-0.546015,942,1176
52,InventorySkew,SellPressure,99.864318,99.890072,99.929460,0.005719,-10,998.096560,-0.546617,954,1176
53,InventorySkew,SellPressure,99.857141,99.839761,99.929460,0.005807,0,-0.804164,-0.804164,944,1176
54,InventorySkew,SellPressure,99.870766,99.839761,99.930306,0.006276,0,-0.804164,-0.804164,944,1168
55,InventorySkew,SellPressure,99.862087,99.839761,99.930306,0.006420,0,-0.804164,-0.804164,934,1168
56,InventorySkew,SellPressure,99.849311,99.800000,99.930306,0.006801,0,-0.804164,-0.804164,922,1168
57,InventorySkew,SellPressure,99.860700,99.800000,99.941530,0.007077,0,-0.804164,-0.804164,922,1156
58,InventorySkew,SellPressure,99.845484,99.800000,99.941530,0.007565,0,-0.804164,-0.804164,921,1156
59,InventorySkew,SellPressure,99.858672,99.800000,99.941530,0.007903,0,-0.804164,-0.804164,921,1150
60,InventorySkew,SellPressure,99.859650,99.809650,99.909650,0.007487,0,-0.804164,-0.804164,931,1161
61,InventorySkew,SellPressure,99.844334,99.809650,99.909650,0.007957,8,-799.281366,-0.526691,923,1161
62,InventorySkew,SellPressure,99.853324,99.809650,99.941530,0.008019,-2,199.815136,0.108489,923,1151
63,InventorySkew,SellPressure,99.852295,99.809650,99.941530,0.007599,-2,199.815136,0.110546,942,1151
64,InventorySkew,SellPressure,99.843005,99.800000,99.941530,0.007701,0,0.195836,0.195836,929,1151
65,InventorySkew,SellPressure,99.845485,99.800000,99.941530,0.007388,0,0.195836,0.195836,939,1151
66,InventorySkew,SellPressure,99.848087,99.812008,99.941530,0.007100,0,0.195836,0.195836,959,1151
67,InventorySkew,SellPressure,99.846098,99.812008,99.941530,0.006794,0,0.195836,0.195836,974,1151
68,InventorySkew,SellPressure,99.850965,99.812008,99.941530,0.006678,0,0.195836,0.195836,976,1151
69,InventorySkew,SellPressure,99.860944,99.812008,99.964381,0.006876,0,0.195836,0.195836,976,1139
70,InventorySkew,SellPressure,99.852779,99.812008,99.902779,0.006954,0,0.195836,0.195836,971,1149
71,InventorySkew,SellPressure,99.855900,99.812008,99.902779,0.006724,0,0.195836,0.195836,987,1149
72,InventorySkew,SellPressure,99.843352,99.800000,99.902779,0.007073,10,-997.831949,0.601572,971,1149
73,InventorySkew,SellPressure,99.830109,99.800000,99.902779,0.007443,10,-997.831949,0.469139,952,1149
74,InventorySkew,SellPressure,99.837787,99.800000,99.971944,0.007457,0,1.195836,1.195836,952,1132
75,InventorySkew,SellPressure,99.850032,99.800000,99.971944,0.007745,0,1.195836,1.195836,952,1124
76,InventorySkew,SellPressure,99.838892,99.796876,99.971944,0.007948,7,-697.382295,1.489949,938,1124
77,InventorySkew,SellPressure,99.824940,99.796876,99.971944,0.008309,9,-896.976047,1.448410,936,1124
78,InventorySkew,SellPressure,99.822925,99.796876,99.887474,0.007931,9,-896.976047,1.430275,936,1125
79,InventorySkew,SellPressure,99.826036,99.796876,99.887474,0.007642,9,-896.976047,1.458277,936,1126
